[2025-09-24T17:34:56.370+0000] {taskinstance.py:1956} INFO - Dependencies all met for dep_context=non-requeueable deps ti=<TaskInstance: dag_etl_neotass.load scheduled__2025-09-23T00:00:00+00:00 [queued]>
[2025-09-24T17:34:56.484+0000] {taskinstance.py:1956} INFO - Dependencies all met for dep_context=requeueable deps ti=<TaskInstance: dag_etl_neotass.load scheduled__2025-09-23T00:00:00+00:00 [queued]>
[2025-09-24T17:34:56.489+0000] {taskinstance.py:2170} INFO - Starting attempt 1 of 2
[2025-09-24T17:34:56.706+0000] {taskinstance.py:2191} INFO - Executing <Task(PythonOperator): load> on 2025-09-23 00:00:00+00:00
[2025-09-24T17:34:56.808+0000] {standard_task_runner.py:60} INFO - Started process 4719 to run task
[2025-09-24T17:34:56.829+0000] {standard_task_runner.py:87} INFO - Running: ['***', 'tasks', 'run', 'dag_etl_neotass', 'load', 'scheduled__2025-09-23T00:00:00+00:00', '--job-id', '4', '--raw', '--subdir', 'DAGS_FOLDER/dag_etl_neotass.py', '--cfg-path', '/tmp/tmpm6d32026']
[2025-09-24T17:34:56.850+0000] {standard_task_runner.py:88} INFO - Job 4: Subtask load
[2025-09-24T17:34:57.369+0000] {task_command.py:423} INFO - Running <TaskInstance: dag_etl_neotass.load scheduled__2025-09-23T00:00:00+00:00 [running]> on host dd5518020916
[2025-09-24T17:34:58.010+0000] {taskinstance.py:2480} INFO - Exporting env vars: AIRFLOW_CTX_DAG_OWNER='***' AIRFLOW_CTX_DAG_ID='dag_etl_neotass' AIRFLOW_CTX_TASK_ID='load' AIRFLOW_CTX_EXECUTION_DATE='2025-09-23T00:00:00+00:00' AIRFLOW_CTX_TRY_NUMBER='1' AIRFLOW_CTX_DAG_RUN_ID='scheduled__2025-09-23T00:00:00+00:00'
[2025-09-24T17:34:58.031+0000] {taskinstance.py:2698} ERROR - Task failed with exception
Traceback (most recent call last):
  File "/home/airflow/.local/lib/python3.8/site-packages/airflow/models/taskinstance.py", line 433, in _execute_task
    result = execute_callable(context=context, **execute_callable_kwargs)
  File "/home/airflow/.local/lib/python3.8/site-packages/airflow/operators/python.py", line 199, in execute
    return_value = self.execute_callable()
  File "/home/airflow/.local/lib/python3.8/site-packages/airflow/operators/python.py", line 216, in execute_callable
    return self.python_callable(*self.op_args, **self.op_kwargs)
  File "/opt/airflow/dags/dag_etl_neotass.py", line 100, in load
    from ..data_warehouse.models import dim_parceiro, dim_produto, fato_registro_oportunidade, fato_sellout
ImportError: attempted relative import with no known parent package
[2025-09-24T17:34:58.166+0000] {taskinstance.py:1138} INFO - Marking task as UP_FOR_RETRY. dag_id=dag_etl_neotass, task_id=load, execution_date=20250923T000000, start_date=20250924T173456, end_date=20250924T173458
[2025-09-24T17:34:58.369+0000] {standard_task_runner.py:107} ERROR - Failed to execute job 4 for task load (attempted relative import with no known parent package; 4719)
[2025-09-24T17:34:58.442+0000] {local_task_job_runner.py:234} INFO - Task exited with return code 1
[2025-09-24T17:34:58.640+0000] {taskinstance.py:3280} INFO - 0 downstream tasks scheduled from follow-on schedule check
[2025-09-24T17:44:53.810+0000] {taskinstance.py:1956} INFO - Dependencies all met for dep_context=non-requeueable deps ti=<TaskInstance: dag_etl_neotass.load scheduled__2025-09-23T00:00:00+00:00 [queued]>
[2025-09-24T17:44:53.856+0000] {taskinstance.py:1956} INFO - Dependencies all met for dep_context=requeueable deps ti=<TaskInstance: dag_etl_neotass.load scheduled__2025-09-23T00:00:00+00:00 [queued]>
[2025-09-24T17:44:53.858+0000] {taskinstance.py:2170} INFO - Starting attempt 1 of 2
[2025-09-24T17:44:54.082+0000] {taskinstance.py:2191} INFO - Executing <Task(PythonOperator): load> on 2025-09-23 00:00:00+00:00
[2025-09-24T17:44:54.133+0000] {standard_task_runner.py:60} INFO - Started process 1295 to run task
[2025-09-24T17:44:54.192+0000] {standard_task_runner.py:87} INFO - Running: ['***', 'tasks', 'run', 'dag_etl_neotass', 'load', 'scheduled__2025-09-23T00:00:00+00:00', '--job-id', '4', '--raw', '--subdir', 'DAGS_FOLDER/dag_etl_neotass.py', '--cfg-path', '/tmp/tmp49hxdold']
[2025-09-24T17:44:54.202+0000] {standard_task_runner.py:88} INFO - Job 4: Subtask load
[2025-09-24T17:44:54.879+0000] {task_command.py:423} INFO - Running <TaskInstance: dag_etl_neotass.load scheduled__2025-09-23T00:00:00+00:00 [running]> on host ff9a178a756b
[2025-09-24T17:44:55.561+0000] {taskinstance.py:2480} INFO - Exporting env vars: AIRFLOW_CTX_DAG_OWNER='***' AIRFLOW_CTX_DAG_ID='dag_etl_neotass' AIRFLOW_CTX_TASK_ID='load' AIRFLOW_CTX_EXECUTION_DATE='2025-09-23T00:00:00+00:00' AIRFLOW_CTX_TRY_NUMBER='1' AIRFLOW_CTX_DAG_RUN_ID='scheduled__2025-09-23T00:00:00+00:00'
[2025-09-24T17:44:55.855+0000] {taskinstance.py:2698} ERROR - Task failed with exception
Traceback (most recent call last):
  File "/home/airflow/.local/lib/python3.8/site-packages/airflow/models/taskinstance.py", line 433, in _execute_task
    result = execute_callable(context=context, **execute_callable_kwargs)
  File "/home/airflow/.local/lib/python3.8/site-packages/airflow/operators/python.py", line 199, in execute
    return_value = self.execute_callable()
  File "/home/airflow/.local/lib/python3.8/site-packages/airflow/operators/python.py", line 216, in execute_callable
    return self.python_callable(*self.op_args, **self.op_kwargs)
  File "/opt/airflow/dags/dag_etl_neotass.py", line 104, in load
    dim_parceiro_df = pd.read_csv('/opt/airflow/data_warehouse/dim_parceiro.csv')
  File "/home/airflow/.local/lib/python3.8/site-packages/pandas/io/parsers/readers.py", line 912, in read_csv
    return _read(filepath_or_buffer, kwds)
  File "/home/airflow/.local/lib/python3.8/site-packages/pandas/io/parsers/readers.py", line 577, in _read
    parser = TextFileReader(filepath_or_buffer, **kwds)
  File "/home/airflow/.local/lib/python3.8/site-packages/pandas/io/parsers/readers.py", line 1407, in __init__
    self._engine = self._make_engine(f, self.engine)
  File "/home/airflow/.local/lib/python3.8/site-packages/pandas/io/parsers/readers.py", line 1661, in _make_engine
    self.handles = get_handle(
  File "/home/airflow/.local/lib/python3.8/site-packages/pandas/io/common.py", line 859, in get_handle
    handle = open(
FileNotFoundError: [Errno 2] No such file or directory: '/opt/airflow/data_warehouse/dim_parceiro.csv'
[2025-09-24T17:44:55.953+0000] {taskinstance.py:1138} INFO - Marking task as UP_FOR_RETRY. dag_id=dag_etl_neotass, task_id=load, execution_date=20250923T000000, start_date=20250924T174453, end_date=20250924T174455
[2025-09-24T17:44:56.173+0000] {standard_task_runner.py:107} ERROR - Failed to execute job 4 for task load ([Errno 2] No such file or directory: '/opt/airflow/data_warehouse/dim_parceiro.csv'; 1295)
[2025-09-24T17:44:56.399+0000] {local_task_job_runner.py:234} INFO - Task exited with return code 1
[2025-09-24T17:44:57.339+0000] {taskinstance.py:3280} INFO - 0 downstream tasks scheduled from follow-on schedule check
[2025-09-24T17:58:05.555+0000] {taskinstance.py:1956} INFO - Dependencies all met for dep_context=non-requeueable deps ti=<TaskInstance: dag_etl_neotass.load scheduled__2025-09-23T00:00:00+00:00 [queued]>
[2025-09-24T17:58:05.594+0000] {taskinstance.py:1956} INFO - Dependencies all met for dep_context=requeueable deps ti=<TaskInstance: dag_etl_neotass.load scheduled__2025-09-23T00:00:00+00:00 [queued]>
[2025-09-24T17:58:05.596+0000] {taskinstance.py:2170} INFO - Starting attempt 1 of 2
[2025-09-24T17:58:05.659+0000] {taskinstance.py:2191} INFO - Executing <Task(PythonOperator): load> on 2025-09-23 00:00:00+00:00
[2025-09-24T17:58:05.685+0000] {standard_task_runner.py:60} INFO - Started process 2985 to run task
[2025-09-24T17:58:05.699+0000] {standard_task_runner.py:87} INFO - Running: ['***', 'tasks', 'run', 'dag_etl_neotass', 'load', 'scheduled__2025-09-23T00:00:00+00:00', '--job-id', '4', '--raw', '--subdir', 'DAGS_FOLDER/dag_etl_neotass.py', '--cfg-path', '/tmp/tmp1bp96vpf']
[2025-09-24T17:58:05.718+0000] {standard_task_runner.py:88} INFO - Job 4: Subtask load
[2025-09-24T17:58:05.862+0000] {task_command.py:423} INFO - Running <TaskInstance: dag_etl_neotass.load scheduled__2025-09-23T00:00:00+00:00 [running]> on host c88dd78f10f0
[2025-09-24T17:58:06.099+0000] {taskinstance.py:2480} INFO - Exporting env vars: AIRFLOW_CTX_DAG_OWNER='***' AIRFLOW_CTX_DAG_ID='dag_etl_neotass' AIRFLOW_CTX_TASK_ID='load' AIRFLOW_CTX_EXECUTION_DATE='2025-09-23T00:00:00+00:00' AIRFLOW_CTX_TRY_NUMBER='1' AIRFLOW_CTX_DAG_RUN_ID='scheduled__2025-09-23T00:00:00+00:00'
[2025-09-24T17:58:06.376+0000] {taskinstance.py:2698} ERROR - Task failed with exception
Traceback (most recent call last):
  File "/home/airflow/.local/lib/python3.8/site-packages/airflow/models/taskinstance.py", line 433, in _execute_task
    result = execute_callable(context=context, **execute_callable_kwargs)
  File "/home/airflow/.local/lib/python3.8/site-packages/airflow/operators/python.py", line 199, in execute
    return_value = self.execute_callable()
  File "/home/airflow/.local/lib/python3.8/site-packages/airflow/operators/python.py", line 216, in execute_callable
    return self.python_callable(*self.op_args, **self.op_kwargs)
  File "/opt/airflow/dags/dag_etl_neotass.py", line 114, in load
    dim_parceiro_df_chunk.to_sql('dim_parceiro', con=dim_parceiro.engine, if_exists='append', index=False)
AttributeError: type object 'dim_parceiro' has no attribute 'engine'
[2025-09-24T17:58:06.395+0000] {taskinstance.py:1138} INFO - Marking task as UP_FOR_RETRY. dag_id=dag_etl_neotass, task_id=load, execution_date=20250923T000000, start_date=20250924T175805, end_date=20250924T175806
[2025-09-24T17:58:06.421+0000] {standard_task_runner.py:107} ERROR - Failed to execute job 4 for task load (type object 'dim_parceiro' has no attribute 'engine'; 2985)
[2025-09-24T17:58:06.446+0000] {local_task_job_runner.py:234} INFO - Task exited with return code 1
[2025-09-24T17:58:06.482+0000] {taskinstance.py:3280} INFO - 0 downstream tasks scheduled from follow-on schedule check
