[2025-09-24T17:40:06.976+0000] {taskinstance.py:1956} INFO - Dependencies all met for dep_context=non-requeueable deps ti=<TaskInstance: dag_etl_neotass.load scheduled__2025-09-23T00:00:00+00:00 [queued]>
[2025-09-24T17:40:07.005+0000] {taskinstance.py:1956} INFO - Dependencies all met for dep_context=requeueable deps ti=<TaskInstance: dag_etl_neotass.load scheduled__2025-09-23T00:00:00+00:00 [queued]>
[2025-09-24T17:40:07.006+0000] {taskinstance.py:2170} INFO - Starting attempt 2 of 2
[2025-09-24T17:40:07.056+0000] {taskinstance.py:2191} INFO - Executing <Task(PythonOperator): load> on 2025-09-23 00:00:00+00:00
[2025-09-24T17:40:07.086+0000] {standard_task_runner.py:60} INFO - Started process 7257 to run task
[2025-09-24T17:40:07.097+0000] {standard_task_runner.py:87} INFO - Running: ['***', 'tasks', 'run', 'dag_etl_neotass', 'load', 'scheduled__2025-09-23T00:00:00+00:00', '--job-id', '5', '--raw', '--subdir', 'DAGS_FOLDER/dag_etl_neotass.py', '--cfg-path', '/tmp/tmp63hzg9jd']
[2025-09-24T17:40:07.105+0000] {standard_task_runner.py:88} INFO - Job 5: Subtask load
[2025-09-24T17:40:07.312+0000] {task_command.py:423} INFO - Running <TaskInstance: dag_etl_neotass.load scheduled__2025-09-23T00:00:00+00:00 [running]> on host dd5518020916
[2025-09-24T17:40:07.924+0000] {taskinstance.py:2480} INFO - Exporting env vars: AIRFLOW_CTX_DAG_OWNER='***' AIRFLOW_CTX_DAG_ID='dag_etl_neotass' AIRFLOW_CTX_TASK_ID='load' AIRFLOW_CTX_EXECUTION_DATE='2025-09-23T00:00:00+00:00' AIRFLOW_CTX_TRY_NUMBER='2' AIRFLOW_CTX_DAG_RUN_ID='scheduled__2025-09-23T00:00:00+00:00'
[2025-09-24T17:40:08.487+0000] {taskinstance.py:2698} ERROR - Task failed with exception
Traceback (most recent call last):
  File "/home/airflow/.local/lib/python3.8/site-packages/airflow/models/taskinstance.py", line 433, in _execute_task
    result = execute_callable(context=context, **execute_callable_kwargs)
  File "/home/airflow/.local/lib/python3.8/site-packages/airflow/operators/python.py", line 199, in execute
    return_value = self.execute_callable()
  File "/home/airflow/.local/lib/python3.8/site-packages/airflow/operators/python.py", line 216, in execute_callable
    return self.python_callable(*self.op_args, **self.op_kwargs)
  File "/opt/airflow/dags/dag_etl_neotass.py", line 114, in load
    dim_parceiro_df_chunk.to_sql('dim_parceiro', con=dim_parceiro.engine, if_exists='append', index=False)
AttributeError: type object 'dim_parceiro' has no attribute 'engine'
[2025-09-24T17:40:08.582+0000] {taskinstance.py:1138} INFO - Marking task as FAILED. dag_id=dag_etl_neotass, task_id=load, execution_date=20250923T000000, start_date=20250924T174006, end_date=20250924T174008
[2025-09-24T17:40:08.747+0000] {standard_task_runner.py:107} ERROR - Failed to execute job 5 for task load (type object 'dim_parceiro' has no attribute 'engine'; 7257)
[2025-09-24T17:40:08.898+0000] {local_task_job_runner.py:234} INFO - Task exited with return code 1
[2025-09-24T17:40:09.072+0000] {taskinstance.py:3280} INFO - 0 downstream tasks scheduled from follow-on schedule check
[2025-09-24T17:50:01.774+0000] {taskinstance.py:1956} INFO - Dependencies all met for dep_context=non-requeueable deps ti=<TaskInstance: dag_etl_neotass.load scheduled__2025-09-23T00:00:00+00:00 [queued]>
[2025-09-24T17:50:01.808+0000] {taskinstance.py:1956} INFO - Dependencies all met for dep_context=requeueable deps ti=<TaskInstance: dag_etl_neotass.load scheduled__2025-09-23T00:00:00+00:00 [queued]>
[2025-09-24T17:50:01.809+0000] {taskinstance.py:2170} INFO - Starting attempt 2 of 2
[2025-09-24T17:50:01.874+0000] {taskinstance.py:2191} INFO - Executing <Task(PythonOperator): load> on 2025-09-23 00:00:00+00:00
[2025-09-24T17:50:01.897+0000] {standard_task_runner.py:60} INFO - Started process 3803 to run task
[2025-09-24T17:50:01.915+0000] {standard_task_runner.py:87} INFO - Running: ['***', 'tasks', 'run', 'dag_etl_neotass', 'load', 'scheduled__2025-09-23T00:00:00+00:00', '--job-id', '5', '--raw', '--subdir', 'DAGS_FOLDER/dag_etl_neotass.py', '--cfg-path', '/tmp/tmpi48g_09w']
[2025-09-24T17:50:01.933+0000] {standard_task_runner.py:88} INFO - Job 5: Subtask load
[2025-09-24T17:50:02.128+0000] {task_command.py:423} INFO - Running <TaskInstance: dag_etl_neotass.load scheduled__2025-09-23T00:00:00+00:00 [running]> on host ff9a178a756b
[2025-09-24T17:50:02.409+0000] {taskinstance.py:2480} INFO - Exporting env vars: AIRFLOW_CTX_DAG_OWNER='***' AIRFLOW_CTX_DAG_ID='dag_etl_neotass' AIRFLOW_CTX_TASK_ID='load' AIRFLOW_CTX_EXECUTION_DATE='2025-09-23T00:00:00+00:00' AIRFLOW_CTX_TRY_NUMBER='2' AIRFLOW_CTX_DAG_RUN_ID='scheduled__2025-09-23T00:00:00+00:00'
[2025-09-24T17:50:02.593+0000] {taskinstance.py:2698} ERROR - Task failed with exception
Traceback (most recent call last):
  File "/home/airflow/.local/lib/python3.8/site-packages/airflow/models/taskinstance.py", line 433, in _execute_task
    result = execute_callable(context=context, **execute_callable_kwargs)
  File "/home/airflow/.local/lib/python3.8/site-packages/airflow/operators/python.py", line 199, in execute
    return_value = self.execute_callable()
  File "/home/airflow/.local/lib/python3.8/site-packages/airflow/operators/python.py", line 216, in execute_callable
    return self.python_callable(*self.op_args, **self.op_kwargs)
  File "/opt/airflow/dags/dag_etl_neotass.py", line 104, in load
    dim_parceiro_df = pd.read_csv('/opt/airflow/data_warehouse/dim_parceiro.csv')
  File "/home/airflow/.local/lib/python3.8/site-packages/pandas/io/parsers/readers.py", line 912, in read_csv
    return _read(filepath_or_buffer, kwds)
  File "/home/airflow/.local/lib/python3.8/site-packages/pandas/io/parsers/readers.py", line 577, in _read
    parser = TextFileReader(filepath_or_buffer, **kwds)
  File "/home/airflow/.local/lib/python3.8/site-packages/pandas/io/parsers/readers.py", line 1407, in __init__
    self._engine = self._make_engine(f, self.engine)
  File "/home/airflow/.local/lib/python3.8/site-packages/pandas/io/parsers/readers.py", line 1661, in _make_engine
    self.handles = get_handle(
  File "/home/airflow/.local/lib/python3.8/site-packages/pandas/io/common.py", line 859, in get_handle
    handle = open(
FileNotFoundError: [Errno 2] No such file or directory: '/opt/airflow/data_warehouse/dim_parceiro.csv'
[2025-09-24T17:50:02.631+0000] {taskinstance.py:1138} INFO - Marking task as FAILED. dag_id=dag_etl_neotass, task_id=load, execution_date=20250923T000000, start_date=20250924T175001, end_date=20250924T175002
[2025-09-24T17:50:02.701+0000] {standard_task_runner.py:107} ERROR - Failed to execute job 5 for task load ([Errno 2] No such file or directory: '/opt/airflow/data_warehouse/dim_parceiro.csv'; 3803)
[2025-09-24T17:50:02.783+0000] {local_task_job_runner.py:234} INFO - Task exited with return code 1
[2025-09-24T17:50:02.859+0000] {taskinstance.py:3280} INFO - 0 downstream tasks scheduled from follow-on schedule check
[2025-09-24T18:03:19.699+0000] {taskinstance.py:1956} INFO - Dependencies all met for dep_context=non-requeueable deps ti=<TaskInstance: dag_etl_neotass.load scheduled__2025-09-23T00:00:00+00:00 [queued]>
[2025-09-24T18:03:19.740+0000] {taskinstance.py:1956} INFO - Dependencies all met for dep_context=requeueable deps ti=<TaskInstance: dag_etl_neotass.load scheduled__2025-09-23T00:00:00+00:00 [queued]>
[2025-09-24T18:03:19.741+0000] {taskinstance.py:2170} INFO - Starting attempt 2 of 2
[2025-09-24T18:03:19.793+0000] {taskinstance.py:2191} INFO - Executing <Task(PythonOperator): load> on 2025-09-23 00:00:00+00:00
[2025-09-24T18:03:19.837+0000] {standard_task_runner.py:87} INFO - Running: ['***', 'tasks', 'run', 'dag_etl_neotass', 'load', 'scheduled__2025-09-23T00:00:00+00:00', '--job-id', '7', '--raw', '--subdir', 'DAGS_FOLDER/dag_etl_neotass.py', '--cfg-path', '/tmp/tmpso22pnuf']
[2025-09-24T18:03:19.845+0000] {standard_task_runner.py:88} INFO - Job 7: Subtask load
[2025-09-24T18:03:19.824+0000] {standard_task_runner.py:60} INFO - Started process 1142 to run task
[2025-09-24T18:03:20.432+0000] {task_command.py:423} INFO - Running <TaskInstance: dag_etl_neotass.load scheduled__2025-09-23T00:00:00+00:00 [running]> on host 3bb0673bd533
[2025-09-24T18:03:21.684+0000] {taskinstance.py:2480} INFO - Exporting env vars: AIRFLOW_CTX_DAG_OWNER='***' AIRFLOW_CTX_DAG_ID='dag_etl_neotass' AIRFLOW_CTX_TASK_ID='load' AIRFLOW_CTX_EXECUTION_DATE='2025-09-23T00:00:00+00:00' AIRFLOW_CTX_TRY_NUMBER='2' AIRFLOW_CTX_DAG_RUN_ID='scheduled__2025-09-23T00:00:00+00:00'
[2025-09-24T18:03:23.941+0000] {logging_mixin.py:188} WARNING - /opt/***/dags/dag_etl_neotass.py:114 UserWarning: pandas only supports SQLAlchemy connectable (engine/connection) or database string URI or sqlite3 DBAPI2 connection. Other DBAPI2 objects are not tested. Please consider using SQLAlchemy.
[2025-09-24T18:03:23.957+0000] {taskinstance.py:2698} ERROR - Task failed with exception
Traceback (most recent call last):
  File "/home/airflow/.local/lib/python3.8/site-packages/airflow/models/taskinstance.py", line 433, in _execute_task
    result = execute_callable(context=context, **execute_callable_kwargs)
  File "/home/airflow/.local/lib/python3.8/site-packages/airflow/operators/python.py", line 199, in execute
    return_value = self.execute_callable()
  File "/home/airflow/.local/lib/python3.8/site-packages/airflow/operators/python.py", line 216, in execute_callable
    return self.python_callable(*self.op_args, **self.op_kwargs)
  File "/opt/airflow/dags/dag_etl_neotass.py", line 114, in load
    dim_parceiro_df_chunk.to_sql('dim_parceiro', con=dim_parceiro, if_exists='append', index=False)
  File "/home/airflow/.local/lib/python3.8/site-packages/pandas/core/generic.py", line 2878, in to_sql
    return sql.to_sql(
  File "/home/airflow/.local/lib/python3.8/site-packages/pandas/io/sql.py", line 769, in to_sql
    return pandas_sql.to_sql(
  File "/home/airflow/.local/lib/python3.8/site-packages/pandas/io/sql.py", line 2378, in to_sql
    table.create()
  File "/home/airflow/.local/lib/python3.8/site-packages/pandas/io/sql.py", line 903, in create
    if self.exists():
  File "/home/airflow/.local/lib/python3.8/site-packages/pandas/io/sql.py", line 889, in exists
    return self.pd_sql.has_table(self.name, self.schema)
  File "/home/airflow/.local/lib/python3.8/site-packages/pandas/io/sql.py", line 2385, in has_table
    return len(self.execute(query, [name]).fetchall()) > 0
  File "/home/airflow/.local/lib/python3.8/site-packages/pandas/io/sql.py", line 2200, in execute
    cur = self.con.cursor()
AttributeError: type object 'dim_parceiro' has no attribute 'cursor'
[2025-09-24T18:03:24.181+0000] {taskinstance.py:1138} INFO - Marking task as FAILED. dag_id=dag_etl_neotass, task_id=load, execution_date=20250923T000000, start_date=20250924T180319, end_date=20250924T180324
[2025-09-24T18:03:24.559+0000] {standard_task_runner.py:107} ERROR - Failed to execute job 7 for task load (type object 'dim_parceiro' has no attribute 'cursor'; 1142)
[2025-09-24T18:03:24.617+0000] {local_task_job_runner.py:234} INFO - Task exited with return code 1
[2025-09-24T18:03:25.145+0000] {taskinstance.py:3280} INFO - 0 downstream tasks scheduled from follow-on schedule check
