[2025-09-24T18:03:45.261+0000] {taskinstance.py:1956} INFO - Dependencies all met for dep_context=non-requeueable deps ti=<TaskInstance: dag_etl_neotass.load manual__2025-09-24T18:03:05.736693+00:00 [queued]>
[2025-09-24T18:03:45.307+0000] {taskinstance.py:1956} INFO - Dependencies all met for dep_context=requeueable deps ti=<TaskInstance: dag_etl_neotass.load manual__2025-09-24T18:03:05.736693+00:00 [queued]>
[2025-09-24T18:03:45.309+0000] {taskinstance.py:2170} INFO - Starting attempt 1 of 2
[2025-09-24T18:03:45.383+0000] {taskinstance.py:2191} INFO - Executing <Task(PythonOperator): load> on 2025-09-24 18:03:05.736693+00:00
[2025-09-24T18:03:45.415+0000] {standard_task_runner.py:60} INFO - Started process 1342 to run task
[2025-09-24T18:03:45.440+0000] {standard_task_runner.py:87} INFO - Running: ['***', 'tasks', 'run', 'dag_etl_neotass', 'load', 'manual__2025-09-24T18:03:05.736693+00:00', '--job-id', '9', '--raw', '--subdir', 'DAGS_FOLDER/dag_etl_neotass.py', '--cfg-path', '/tmp/tmpdizsmj7u']
[2025-09-24T18:03:45.449+0000] {standard_task_runner.py:88} INFO - Job 9: Subtask load
[2025-09-24T18:03:46.146+0000] {task_command.py:423} INFO - Running <TaskInstance: dag_etl_neotass.load manual__2025-09-24T18:03:05.736693+00:00 [running]> on host 3bb0673bd533
[2025-09-24T18:03:46.972+0000] {taskinstance.py:2480} INFO - Exporting env vars: AIRFLOW_CTX_DAG_OWNER='***' AIRFLOW_CTX_DAG_ID='dag_etl_neotass' AIRFLOW_CTX_TASK_ID='load' AIRFLOW_CTX_EXECUTION_DATE='2025-09-24T18:03:05.736693+00:00' AIRFLOW_CTX_TRY_NUMBER='1' AIRFLOW_CTX_DAG_RUN_ID='manual__2025-09-24T18:03:05.736693+00:00'
[2025-09-24T18:03:48.143+0000] {logging_mixin.py:188} WARNING - /opt/***/dags/dag_etl_neotass.py:114 UserWarning: pandas only supports SQLAlchemy connectable (engine/connection) or database string URI or sqlite3 DBAPI2 connection. Other DBAPI2 objects are not tested. Please consider using SQLAlchemy.
[2025-09-24T18:03:48.161+0000] {taskinstance.py:2698} ERROR - Task failed with exception
Traceback (most recent call last):
  File "/home/airflow/.local/lib/python3.8/site-packages/airflow/models/taskinstance.py", line 433, in _execute_task
    result = execute_callable(context=context, **execute_callable_kwargs)
  File "/home/airflow/.local/lib/python3.8/site-packages/airflow/operators/python.py", line 199, in execute
    return_value = self.execute_callable()
  File "/home/airflow/.local/lib/python3.8/site-packages/airflow/operators/python.py", line 216, in execute_callable
    return self.python_callable(*self.op_args, **self.op_kwargs)
  File "/opt/airflow/dags/dag_etl_neotass.py", line 114, in load
    dim_parceiro_df_chunk.to_sql('dim_parceiro', con=dim_parceiro, if_exists='append', index=False)
  File "/home/airflow/.local/lib/python3.8/site-packages/pandas/core/generic.py", line 2878, in to_sql
    return sql.to_sql(
  File "/home/airflow/.local/lib/python3.8/site-packages/pandas/io/sql.py", line 769, in to_sql
    return pandas_sql.to_sql(
  File "/home/airflow/.local/lib/python3.8/site-packages/pandas/io/sql.py", line 2378, in to_sql
    table.create()
  File "/home/airflow/.local/lib/python3.8/site-packages/pandas/io/sql.py", line 903, in create
    if self.exists():
  File "/home/airflow/.local/lib/python3.8/site-packages/pandas/io/sql.py", line 889, in exists
    return self.pd_sql.has_table(self.name, self.schema)
  File "/home/airflow/.local/lib/python3.8/site-packages/pandas/io/sql.py", line 2385, in has_table
    return len(self.execute(query, [name]).fetchall()) > 0
  File "/home/airflow/.local/lib/python3.8/site-packages/pandas/io/sql.py", line 2200, in execute
    cur = self.con.cursor()
AttributeError: type object 'dim_parceiro' has no attribute 'cursor'
[2025-09-24T18:03:48.235+0000] {taskinstance.py:1138} INFO - Marking task as UP_FOR_RETRY. dag_id=dag_etl_neotass, task_id=load, execution_date=20250924T180305, start_date=20250924T180345, end_date=20250924T180348
[2025-09-24T18:03:48.285+0000] {standard_task_runner.py:107} ERROR - Failed to execute job 9 for task load (type object 'dim_parceiro' has no attribute 'cursor'; 1342)
[2025-09-24T18:03:48.388+0000] {local_task_job_runner.py:234} INFO - Task exited with return code 1
[2025-09-24T18:03:48.496+0000] {taskinstance.py:3280} INFO - 0 downstream tasks scheduled from follow-on schedule check
