[2025-09-24T03:16:32.574+0000] {taskinstance.py:1956} INFO - Dependencies all met for dep_context=non-requeueable deps ti=<TaskInstance: dag_etl.extract scheduled__2025-09-23T00:00:00+00:00 [queued]>
[2025-09-24T03:16:32.804+0000] {taskinstance.py:1956} INFO - Dependencies all met for dep_context=requeueable deps ti=<TaskInstance: dag_etl.extract scheduled__2025-09-23T00:00:00+00:00 [queued]>
[2025-09-24T03:16:32.805+0000] {taskinstance.py:2170} INFO - Starting attempt 2 of 2
[2025-09-24T03:16:33.234+0000] {taskinstance.py:2191} INFO - Executing <Task(PythonOperator): extract> on 2025-09-23 00:00:00+00:00
[2025-09-24T03:16:33.322+0000] {standard_task_runner.py:60} INFO - Started process 5100 to run task
[2025-09-24T03:16:33.370+0000] {standard_task_runner.py:87} INFO - Running: ['***', 'tasks', 'run', 'dag_etl', 'extract', 'scheduled__2025-09-23T00:00:00+00:00', '--job-id', '6', '--raw', '--subdir', 'DAGS_FOLDER/dag_etl_neotass.py', '--cfg-path', '/tmp/tmptf19aind']
[2025-09-24T03:16:33.388+0000] {standard_task_runner.py:88} INFO - Job 6: Subtask extract
[2025-09-24T03:16:33.728+0000] {task_command.py:423} INFO - Running <TaskInstance: dag_etl.extract scheduled__2025-09-23T00:00:00+00:00 [running]> on host a5ae886b41c8
[2025-09-24T03:16:34.522+0000] {taskinstance.py:2480} INFO - Exporting env vars: AIRFLOW_CTX_DAG_OWNER='***' AIRFLOW_CTX_DAG_ID='dag_etl' AIRFLOW_CTX_TASK_ID='extract' AIRFLOW_CTX_EXECUTION_DATE='2025-09-23T00:00:00+00:00' AIRFLOW_CTX_TRY_NUMBER='2' AIRFLOW_CTX_DAG_RUN_ID='scheduled__2025-09-23T00:00:00+00:00'
[2025-09-24T03:16:34.669+0000] {taskinstance.py:2698} ERROR - Task failed with exception
Traceback (most recent call last):
  File "/home/airflow/.local/lib/python3.8/site-packages/airflow/models/taskinstance.py", line 433, in _execute_task
    result = execute_callable(context=context, **execute_callable_kwargs)
  File "/home/airflow/.local/lib/python3.8/site-packages/airflow/operators/python.py", line 199, in execute
    return_value = self.execute_callable()
  File "/home/airflow/.local/lib/python3.8/site-packages/airflow/operators/python.py", line 216, in execute_callable
    return self.python_callable(*self.op_args, **self.op_kwargs)
  File "/opt/airflow/dags/dag_etl_neotass.py", line 27, in extract
    data_oportunidades = pd.read_json('../../database/registros_oportunidades.json')
  File "/home/airflow/.local/lib/python3.8/site-packages/pandas/io/json/_json.py", line 760, in read_json
    json_reader = JsonReader(
  File "/home/airflow/.local/lib/python3.8/site-packages/pandas/io/json/_json.py", line 861, in __init__
    data = self._get_data_from_filepath(filepath_or_buffer)
  File "/home/airflow/.local/lib/python3.8/site-packages/pandas/io/json/_json.py", line 917, in _get_data_from_filepath
    raise FileNotFoundError(f"File {filepath_or_buffer} does not exist")
FileNotFoundError: File ../../database/registros_oportunidades.json does not exist
[2025-09-24T03:16:34.709+0000] {taskinstance.py:1138} INFO - Marking task as FAILED. dag_id=dag_etl, task_id=extract, execution_date=20250923T000000, start_date=20250924T031632, end_date=20250924T031634
[2025-09-24T03:16:34.763+0000] {standard_task_runner.py:107} ERROR - Failed to execute job 6 for task extract (File ../../database/registros_oportunidades.json does not exist; 5100)
[2025-09-24T03:16:34.834+0000] {local_task_job_runner.py:234} INFO - Task exited with return code 1
[2025-09-24T03:16:34.946+0000] {taskinstance.py:3280} INFO - 0 downstream tasks scheduled from follow-on schedule check
