[2025-09-24T03:55:45.080+0000] {taskinstance.py:1956} INFO - Dependencies all met for dep_context=non-requeueable deps ti=<TaskInstance: dag_etl.transform scheduled__2025-09-23T00:00:00+00:00 [queued]>
[2025-09-24T03:55:45.184+0000] {taskinstance.py:1956} INFO - Dependencies all met for dep_context=requeueable deps ti=<TaskInstance: dag_etl.transform scheduled__2025-09-23T00:00:00+00:00 [queued]>
[2025-09-24T03:55:45.190+0000] {taskinstance.py:2170} INFO - Starting attempt 1 of 2
[2025-09-24T03:55:45.490+0000] {taskinstance.py:2191} INFO - Executing <Task(PythonOperator): transform> on 2025-09-23 00:00:00+00:00
[2025-09-24T03:55:45.600+0000] {standard_task_runner.py:60} INFO - Started process 6377 to run task
[2025-09-24T03:55:45.631+0000] {standard_task_runner.py:87} INFO - Running: ['***', 'tasks', 'run', 'dag_etl', 'transform', 'scheduled__2025-09-23T00:00:00+00:00', '--job-id', '4', '--raw', '--subdir', 'DAGS_FOLDER/dag_etl_neotass.py', '--cfg-path', '/tmp/tmpvcb67zvi']
[2025-09-24T03:55:45.639+0000] {standard_task_runner.py:88} INFO - Job 4: Subtask transform
[2025-09-24T03:55:46.220+0000] {task_command.py:423} INFO - Running <TaskInstance: dag_etl.transform scheduled__2025-09-23T00:00:00+00:00 [running]> on host c26bc00dd9a9
[2025-09-24T03:55:47.514+0000] {taskinstance.py:2480} INFO - Exporting env vars: AIRFLOW_CTX_DAG_OWNER='***' AIRFLOW_CTX_DAG_ID='dag_etl' AIRFLOW_CTX_TASK_ID='transform' AIRFLOW_CTX_EXECUTION_DATE='2025-09-23T00:00:00+00:00' AIRFLOW_CTX_TRY_NUMBER='1' AIRFLOW_CTX_DAG_RUN_ID='scheduled__2025-09-23T00:00:00+00:00'
[2025-09-24T03:55:47.526+0000] {taskinstance.py:2698} ERROR - Task failed with exception
Traceback (most recent call last):
  File "/home/airflow/.local/lib/python3.8/site-packages/airflow/models/taskinstance.py", line 433, in _execute_task
    result = execute_callable(context=context, **execute_callable_kwargs)
  File "/home/airflow/.local/lib/python3.8/site-packages/airflow/operators/python.py", line 199, in execute
    return_value = self.execute_callable()
  File "/home/airflow/.local/lib/python3.8/site-packages/airflow/operators/python.py", line 216, in execute_callable
    return self.python_callable(*self.op_args, **self.op_kwargs)
TypeError: transform() missing 2 required positional arguments: 'data_oportunidades' and 'data_sellout'
[2025-09-24T03:55:47.583+0000] {taskinstance.py:1138} INFO - Marking task as UP_FOR_RETRY. dag_id=dag_etl, task_id=transform, execution_date=20250923T000000, start_date=20250924T035545, end_date=20250924T035547
[2025-09-24T03:55:47.633+0000] {standard_task_runner.py:107} ERROR - Failed to execute job 4 for task transform (transform() missing 2 required positional arguments: 'data_oportunidades' and 'data_sellout'; 6377)
[2025-09-24T03:55:47.795+0000] {local_task_job_runner.py:234} INFO - Task exited with return code 1
[2025-09-24T03:55:48.223+0000] {taskinstance.py:3280} INFO - 0 downstream tasks scheduled from follow-on schedule check
[2025-09-24T14:23:53.972+0000] {taskinstance.py:1956} INFO - Dependencies all met for dep_context=non-requeueable deps ti=<TaskInstance: dag_etl.transform scheduled__2025-09-23T00:00:00+00:00 [queued]>
[2025-09-24T14:23:54.046+0000] {taskinstance.py:1956} INFO - Dependencies all met for dep_context=requeueable deps ti=<TaskInstance: dag_etl.transform scheduled__2025-09-23T00:00:00+00:00 [queued]>
[2025-09-24T14:23:54.048+0000] {taskinstance.py:2170} INFO - Starting attempt 1 of 2
[2025-09-24T14:23:54.155+0000] {taskinstance.py:2191} INFO - Executing <Task(PythonOperator): transform> on 2025-09-23 00:00:00+00:00
[2025-09-24T14:23:54.188+0000] {standard_task_runner.py:60} INFO - Started process 1884 to run task
[2025-09-24T14:23:54.218+0000] {standard_task_runner.py:87} INFO - Running: ['***', 'tasks', 'run', 'dag_etl', 'transform', 'scheduled__2025-09-23T00:00:00+00:00', '--job-id', '3', '--raw', '--subdir', 'DAGS_FOLDER/dag_etl_neotass.py', '--cfg-path', '/tmp/tmpzsampam5']
[2025-09-24T14:23:54.229+0000] {standard_task_runner.py:88} INFO - Job 3: Subtask transform
[2025-09-24T14:23:54.873+0000] {task_command.py:423} INFO - Running <TaskInstance: dag_etl.transform scheduled__2025-09-23T00:00:00+00:00 [running]> on host d3b285bc5dd4
[2025-09-24T14:23:56.308+0000] {taskinstance.py:2480} INFO - Exporting env vars: AIRFLOW_CTX_DAG_OWNER='***' AIRFLOW_CTX_DAG_ID='dag_etl' AIRFLOW_CTX_TASK_ID='transform' AIRFLOW_CTX_EXECUTION_DATE='2025-09-23T00:00:00+00:00' AIRFLOW_CTX_TRY_NUMBER='1' AIRFLOW_CTX_DAG_RUN_ID='scheduled__2025-09-23T00:00:00+00:00'
[2025-09-24T14:24:05.858+0000] {logging_mixin.py:188} WARNING - /opt/***/dags/dag_etl_neotass.py:80 SettingWithCopyWarning: 
A value is trying to be set on a copy of a slice from a DataFrame

See the caveats in the documentation: https://pandas.pydata.org/pandas-docs/stable/user_guide/indexing.html#returning-a-view-versus-a-copy
[2025-09-24T14:24:05.868+0000] {taskinstance.py:2698} ERROR - Task failed with exception
Traceback (most recent call last):
  File "/home/airflow/.local/lib/python3.8/site-packages/airflow/models/taskinstance.py", line 433, in _execute_task
    result = execute_callable(context=context, **execute_callable_kwargs)
  File "/home/airflow/.local/lib/python3.8/site-packages/airflow/operators/python.py", line 199, in execute
    return_value = self.execute_callable()
  File "/home/airflow/.local/lib/python3.8/site-packages/airflow/operators/python.py", line 216, in execute_callable
    return self.python_callable(*self.op_args, **self.op_kwargs)
  File "/opt/airflow/dags/dag_etl_neotass.py", line 87, in transform
    os.makedirs('/opt/airflow/data_warehouse')
  File "/usr/local/lib/python3.8/os.py", line 223, in makedirs
    mkdir(name, mode)
FileExistsError: [Errno 17] File exists: '/opt/airflow/data_warehouse'
[2025-09-24T14:24:05.910+0000] {taskinstance.py:1138} INFO - Marking task as UP_FOR_RETRY. dag_id=dag_etl, task_id=transform, execution_date=20250923T000000, start_date=20250924T142353, end_date=20250924T142405
[2025-09-24T14:24:05.970+0000] {standard_task_runner.py:107} ERROR - Failed to execute job 3 for task transform ([Errno 17] File exists: '/opt/airflow/data_warehouse'; 1884)
[2025-09-24T14:24:06.130+0000] {local_task_job_runner.py:234} INFO - Task exited with return code 1
[2025-09-24T14:24:06.250+0000] {taskinstance.py:3280} INFO - 0 downstream tasks scheduled from follow-on schedule check
[2025-09-24T14:38:28.247+0000] {taskinstance.py:1956} INFO - Dependencies all met for dep_context=non-requeueable deps ti=<TaskInstance: dag_etl.transform scheduled__2025-09-23T00:00:00+00:00 [queued]>
[2025-09-24T14:38:28.456+0000] {taskinstance.py:1956} INFO - Dependencies all met for dep_context=requeueable deps ti=<TaskInstance: dag_etl.transform scheduled__2025-09-23T00:00:00+00:00 [queued]>
[2025-09-24T14:38:28.457+0000] {taskinstance.py:2170} INFO - Starting attempt 1 of 2
[2025-09-24T14:38:28.901+0000] {taskinstance.py:2191} INFO - Executing <Task(PythonOperator): transform> on 2025-09-23 00:00:00+00:00
[2025-09-24T14:38:28.929+0000] {standard_task_runner.py:60} INFO - Started process 3054 to run task
[2025-09-24T14:38:28.991+0000] {standard_task_runner.py:87} INFO - Running: ['***', 'tasks', 'run', 'dag_etl', 'transform', 'scheduled__2025-09-23T00:00:00+00:00', '--job-id', '3', '--raw', '--subdir', 'DAGS_FOLDER/dag_etl_neotass.py', '--cfg-path', '/tmp/tmpknjlxhus']
[2025-09-24T14:38:29.053+0000] {standard_task_runner.py:88} INFO - Job 3: Subtask transform
[2025-09-24T14:38:30.429+0000] {task_command.py:423} INFO - Running <TaskInstance: dag_etl.transform scheduled__2025-09-23T00:00:00+00:00 [running]> on host 4fcf806a1155
[2025-09-24T14:38:31.378+0000] {taskinstance.py:2480} INFO - Exporting env vars: AIRFLOW_CTX_DAG_OWNER='***' AIRFLOW_CTX_DAG_ID='dag_etl' AIRFLOW_CTX_TASK_ID='transform' AIRFLOW_CTX_EXECUTION_DATE='2025-09-23T00:00:00+00:00' AIRFLOW_CTX_TRY_NUMBER='1' AIRFLOW_CTX_DAG_RUN_ID='scheduled__2025-09-23T00:00:00+00:00'
[2025-09-24T14:38:35.947+0000] {logging_mixin.py:188} WARNING - /opt/***/dags/dag_etl_neotass.py:80 SettingWithCopyWarning: 
A value is trying to be set on a copy of a slice from a DataFrame

See the caveats in the documentation: https://pandas.pydata.org/pandas-docs/stable/user_guide/indexing.html#returning-a-view-versus-a-copy
[2025-09-24T14:38:35.948+0000] {logging_mixin.py:188} INFO - Directory already exists
[2025-09-24T14:38:35.980+0000] {taskinstance.py:2698} ERROR - Task failed with exception
Traceback (most recent call last):
  File "/home/airflow/.local/lib/python3.8/site-packages/airflow/models/taskinstance.py", line 433, in _execute_task
    result = execute_callable(context=context, **execute_callable_kwargs)
  File "/home/airflow/.local/lib/python3.8/site-packages/airflow/operators/python.py", line 199, in execute
    return_value = self.execute_callable()
  File "/home/airflow/.local/lib/python3.8/site-packages/airflow/operators/python.py", line 216, in execute_callable
    return self.python_callable(*self.op_args, **self.op_kwargs)
  File "/opt/airflow/dags/dag_etl_neotass.py", line 91, in transform
    dim_parceiro.to_csv('/opt/airflow/data_warehouse/dim_parceiro.csv', index=False)
  File "/home/airflow/.local/lib/python3.8/site-packages/pandas/core/generic.py", line 3772, in to_csv
    return DataFrameRenderer(formatter).to_csv(
  File "/home/airflow/.local/lib/python3.8/site-packages/pandas/io/formats/format.py", line 1186, in to_csv
    csv_formatter.save()
  File "/home/airflow/.local/lib/python3.8/site-packages/pandas/io/formats/csvs.py", line 240, in save
    with get_handle(
  File "/home/airflow/.local/lib/python3.8/site-packages/pandas/io/common.py", line 859, in get_handle
    handle = open(
PermissionError: [Errno 13] Permission denied: '/opt/airflow/data_warehouse/dim_parceiro.csv'
[2025-09-24T14:38:36.033+0000] {taskinstance.py:1138} INFO - Marking task as UP_FOR_RETRY. dag_id=dag_etl, task_id=transform, execution_date=20250923T000000, start_date=20250924T143828, end_date=20250924T143836
[2025-09-24T14:38:36.100+0000] {standard_task_runner.py:107} ERROR - Failed to execute job 3 for task transform ([Errno 13] Permission denied: '/opt/airflow/data_warehouse/dim_parceiro.csv'; 3054)
[2025-09-24T14:38:36.169+0000] {local_task_job_runner.py:234} INFO - Task exited with return code 1
[2025-09-24T14:38:36.282+0000] {taskinstance.py:3280} INFO - 0 downstream tasks scheduled from follow-on schedule check
[2025-09-24T15:49:39.431+0000] {taskinstance.py:1956} INFO - Dependencies all met for dep_context=non-requeueable deps ti=<TaskInstance: dag_etl.transform scheduled__2025-09-23T00:00:00+00:00 [queued]>
[2025-09-24T15:49:39.460+0000] {taskinstance.py:1956} INFO - Dependencies all met for dep_context=requeueable deps ti=<TaskInstance: dag_etl.transform scheduled__2025-09-23T00:00:00+00:00 [queued]>
[2025-09-24T15:49:39.461+0000] {taskinstance.py:2170} INFO - Starting attempt 1 of 2
[2025-09-24T15:49:39.513+0000] {taskinstance.py:2191} INFO - Executing <Task(PythonOperator): transform> on 2025-09-23 00:00:00+00:00
[2025-09-24T15:49:39.541+0000] {standard_task_runner.py:60} INFO - Started process 4645 to run task
[2025-09-24T15:49:39.556+0000] {standard_task_runner.py:87} INFO - Running: ['***', 'tasks', 'run', 'dag_etl', 'transform', 'scheduled__2025-09-23T00:00:00+00:00', '--job-id', '3', '--raw', '--subdir', 'DAGS_FOLDER/dag_etl_neotass.py', '--cfg-path', '/tmp/tmpmbr71c3e']
[2025-09-24T15:49:39.566+0000] {standard_task_runner.py:88} INFO - Job 3: Subtask transform
[2025-09-24T15:49:39.727+0000] {task_command.py:423} INFO - Running <TaskInstance: dag_etl.transform scheduled__2025-09-23T00:00:00+00:00 [running]> on host 7cc8531f3420
[2025-09-24T15:49:40.051+0000] {taskinstance.py:2480} INFO - Exporting env vars: AIRFLOW_CTX_DAG_OWNER='***' AIRFLOW_CTX_DAG_ID='dag_etl' AIRFLOW_CTX_TASK_ID='transform' AIRFLOW_CTX_EXECUTION_DATE='2025-09-23T00:00:00+00:00' AIRFLOW_CTX_TRY_NUMBER='1' AIRFLOW_CTX_DAG_RUN_ID='scheduled__2025-09-23T00:00:00+00:00'
[2025-09-24T15:49:44.382+0000] {logging_mixin.py:188} WARNING - /opt/***/dags/dag_etl_neotass.py:80 SettingWithCopyWarning: 
A value is trying to be set on a copy of a slice from a DataFrame

See the caveats in the documentation: https://pandas.pydata.org/pandas-docs/stable/user_guide/indexing.html#returning-a-view-versus-a-copy
[2025-09-24T15:49:44.384+0000] {logging_mixin.py:188} INFO - Directory already exists
[2025-09-24T15:49:44.386+0000] {taskinstance.py:2698} ERROR - Task failed with exception
Traceback (most recent call last):
  File "/home/airflow/.local/lib/python3.8/site-packages/airflow/models/taskinstance.py", line 433, in _execute_task
    result = execute_callable(context=context, **execute_callable_kwargs)
  File "/home/airflow/.local/lib/python3.8/site-packages/airflow/operators/python.py", line 199, in execute
    return_value = self.execute_callable()
  File "/home/airflow/.local/lib/python3.8/site-packages/airflow/operators/python.py", line 216, in execute_callable
    return self.python_callable(*self.op_args, **self.op_kwargs)
  File "/opt/airflow/dags/dag_etl_neotass.py", line 91, in transform
    os.chmod('/opt/airflow/data_warehouse', 0o777)
PermissionError: [Errno 1] Operation not permitted: '/opt/airflow/data_warehouse'
[2025-09-24T15:49:44.466+0000] {taskinstance.py:1138} INFO - Marking task as UP_FOR_RETRY. dag_id=dag_etl, task_id=transform, execution_date=20250923T000000, start_date=20250924T154939, end_date=20250924T154944
[2025-09-24T15:49:44.824+0000] {standard_task_runner.py:107} ERROR - Failed to execute job 3 for task transform ([Errno 1] Operation not permitted: '/opt/airflow/data_warehouse'; 4645)
[2025-09-24T15:49:45.259+0000] {local_task_job_runner.py:234} INFO - Task exited with return code 1
[2025-09-24T15:49:45.626+0000] {taskinstance.py:3280} INFO - 0 downstream tasks scheduled from follow-on schedule check
[2025-09-24T16:15:34.986+0000] {taskinstance.py:1956} INFO - Dependencies all met for dep_context=non-requeueable deps ti=<TaskInstance: dag_etl.transform scheduled__2025-09-23T00:00:00+00:00 [queued]>
[2025-09-24T16:15:35.046+0000] {taskinstance.py:1956} INFO - Dependencies all met for dep_context=requeueable deps ti=<TaskInstance: dag_etl.transform scheduled__2025-09-23T00:00:00+00:00 [queued]>
[2025-09-24T16:15:35.051+0000] {taskinstance.py:2170} INFO - Starting attempt 1 of 2
[2025-09-24T16:15:35.278+0000] {taskinstance.py:2191} INFO - Executing <Task(PythonOperator): transform> on 2025-09-23 00:00:00+00:00
[2025-09-24T16:15:35.332+0000] {standard_task_runner.py:60} INFO - Started process 2570 to run task
[2025-09-24T16:15:35.353+0000] {standard_task_runner.py:87} INFO - Running: ['***', 'tasks', 'run', 'dag_etl', 'transform', 'scheduled__2025-09-23T00:00:00+00:00', '--job-id', '3', '--raw', '--subdir', 'DAGS_FOLDER/dag_etl_neotass.py', '--cfg-path', '/tmp/tmpzmxgjzh5']
[2025-09-24T16:15:35.375+0000] {standard_task_runner.py:88} INFO - Job 3: Subtask transform
[2025-09-24T16:15:35.810+0000] {task_command.py:423} INFO - Running <TaskInstance: dag_etl.transform scheduled__2025-09-23T00:00:00+00:00 [running]> on host e75566225659
[2025-09-24T16:15:36.336+0000] {taskinstance.py:2480} INFO - Exporting env vars: AIRFLOW_CTX_DAG_OWNER='***' AIRFLOW_CTX_DAG_ID='dag_etl' AIRFLOW_CTX_TASK_ID='transform' AIRFLOW_CTX_EXECUTION_DATE='2025-09-23T00:00:00+00:00' AIRFLOW_CTX_TRY_NUMBER='1' AIRFLOW_CTX_DAG_RUN_ID='scheduled__2025-09-23T00:00:00+00:00'
[2025-09-24T16:15:41.050+0000] {logging_mixin.py:188} WARNING - /opt/***/dags/dag_etl_neotass.py:80 SettingWithCopyWarning: 
A value is trying to be set on a copy of a slice from a DataFrame

See the caveats in the documentation: https://pandas.pydata.org/pandas-docs/stable/user_guide/indexing.html#returning-a-view-versus-a-copy
[2025-09-24T16:15:41.051+0000] {logging_mixin.py:188} INFO - Directory already exists
[2025-09-24T16:15:41.090+0000] {taskinstance.py:2698} ERROR - Task failed with exception
Traceback (most recent call last):
  File "/home/airflow/.local/lib/python3.8/site-packages/airflow/models/taskinstance.py", line 433, in _execute_task
    result = execute_callable(context=context, **execute_callable_kwargs)
  File "/home/airflow/.local/lib/python3.8/site-packages/airflow/operators/python.py", line 199, in execute
    return_value = self.execute_callable()
  File "/home/airflow/.local/lib/python3.8/site-packages/airflow/operators/python.py", line 216, in execute_callable
    return self.python_callable(*self.op_args, **self.op_kwargs)
  File "/opt/airflow/dags/dag_etl_neotass.py", line 91, in transform
    dim_parceiro.to_csv('/opt/airflow/data_warehouse/dim_parceiro.csv', index=False)
  File "/home/airflow/.local/lib/python3.8/site-packages/pandas/core/generic.py", line 3772, in to_csv
    return DataFrameRenderer(formatter).to_csv(
  File "/home/airflow/.local/lib/python3.8/site-packages/pandas/io/formats/format.py", line 1186, in to_csv
    csv_formatter.save()
  File "/home/airflow/.local/lib/python3.8/site-packages/pandas/io/formats/csvs.py", line 240, in save
    with get_handle(
  File "/home/airflow/.local/lib/python3.8/site-packages/pandas/io/common.py", line 859, in get_handle
    handle = open(
PermissionError: [Errno 13] Permission denied: '/opt/airflow/data_warehouse/dim_parceiro.csv'
[2025-09-24T16:15:41.257+0000] {taskinstance.py:1138} INFO - Marking task as UP_FOR_RETRY. dag_id=dag_etl, task_id=transform, execution_date=20250923T000000, start_date=20250924T161534, end_date=20250924T161541
[2025-09-24T16:15:41.400+0000] {standard_task_runner.py:107} ERROR - Failed to execute job 3 for task transform ([Errno 13] Permission denied: '/opt/airflow/data_warehouse/dim_parceiro.csv'; 2570)
[2025-09-24T16:15:41.581+0000] {local_task_job_runner.py:234} INFO - Task exited with return code 1
[2025-09-24T16:15:41.787+0000] {taskinstance.py:3280} INFO - 0 downstream tasks scheduled from follow-on schedule check
[2025-09-24T16:24:24.079+0000] {taskinstance.py:1956} INFO - Dependencies all met for dep_context=non-requeueable deps ti=<TaskInstance: dag_etl.transform scheduled__2025-09-23T00:00:00+00:00 [queued]>
[2025-09-24T16:24:24.118+0000] {taskinstance.py:1956} INFO - Dependencies all met for dep_context=requeueable deps ti=<TaskInstance: dag_etl.transform scheduled__2025-09-23T00:00:00+00:00 [queued]>
[2025-09-24T16:24:24.122+0000] {taskinstance.py:2170} INFO - Starting attempt 1 of 2
[2025-09-24T16:24:24.549+0000] {taskinstance.py:2191} INFO - Executing <Task(PythonOperator): transform> on 2025-09-23 00:00:00+00:00
[2025-09-24T16:24:24.635+0000] {standard_task_runner.py:60} INFO - Started process 1870 to run task
[2025-09-24T16:24:24.716+0000] {standard_task_runner.py:87} INFO - Running: ['***', 'tasks', 'run', 'dag_etl', 'transform', 'scheduled__2025-09-23T00:00:00+00:00', '--job-id', '3', '--raw', '--subdir', 'DAGS_FOLDER/dag_etl_neotass.py', '--cfg-path', '/tmp/tmpjk3x7ih3']
[2025-09-24T16:24:24.734+0000] {standard_task_runner.py:88} INFO - Job 3: Subtask transform
[2025-09-24T16:24:25.312+0000] {task_command.py:423} INFO - Running <TaskInstance: dag_etl.transform scheduled__2025-09-23T00:00:00+00:00 [running]> on host 7b3a5253326c
[2025-09-24T16:24:26.819+0000] {taskinstance.py:2480} INFO - Exporting env vars: AIRFLOW_CTX_DAG_OWNER='***' AIRFLOW_CTX_DAG_ID='dag_etl' AIRFLOW_CTX_TASK_ID='transform' AIRFLOW_CTX_EXECUTION_DATE='2025-09-23T00:00:00+00:00' AIRFLOW_CTX_TRY_NUMBER='1' AIRFLOW_CTX_DAG_RUN_ID='scheduled__2025-09-23T00:00:00+00:00'
[2025-09-24T16:24:34.137+0000] {logging_mixin.py:188} WARNING - /opt/***/dags/dag_etl_neotass.py:80 SettingWithCopyWarning: 
A value is trying to be set on a copy of a slice from a DataFrame

See the caveats in the documentation: https://pandas.pydata.org/pandas-docs/stable/user_guide/indexing.html#returning-a-view-versus-a-copy
[2025-09-24T16:24:34.139+0000] {logging_mixin.py:188} INFO - Directory already exists
[2025-09-24T16:24:39.360+0000] {python.py:201} INFO - Done. Returned value was: None
[2025-09-24T16:24:39.445+0000] {taskinstance.py:1138} INFO - Marking task as SUCCESS. dag_id=dag_etl, task_id=transform, execution_date=20250923T000000, start_date=20250924T162424, end_date=20250924T162439
[2025-09-24T16:24:39.609+0000] {local_task_job_runner.py:234} INFO - Task exited with return code 0
[2025-09-24T16:24:39.733+0000] {taskinstance.py:3280} INFO - 0 downstream tasks scheduled from follow-on schedule check
