[2025-09-24T03:29:38.590+0000] {taskinstance.py:1956} INFO - Dependencies all met for dep_context=non-requeueable deps ti=<TaskInstance: dag_etl.extract manual__2025-09-24T03:29:29.961297+00:00 [queued]>
[2025-09-24T03:29:38.615+0000] {taskinstance.py:1956} INFO - Dependencies all met for dep_context=requeueable deps ti=<TaskInstance: dag_etl.extract manual__2025-09-24T03:29:29.961297+00:00 [queued]>
[2025-09-24T03:29:38.617+0000] {taskinstance.py:2170} INFO - Starting attempt 1 of 2
[2025-09-24T03:29:38.661+0000] {taskinstance.py:2191} INFO - Executing <Task(PythonOperator): extract> on 2025-09-24 03:29:29.961297+00:00
[2025-09-24T03:29:38.681+0000] {standard_task_runner.py:60} INFO - Started process 1215 to run task
[2025-09-24T03:29:38.701+0000] {standard_task_runner.py:87} INFO - Running: ['***', 'tasks', 'run', 'dag_etl', 'extract', 'manual__2025-09-24T03:29:29.961297+00:00', '--job-id', '9', '--raw', '--subdir', 'DAGS_FOLDER/dag_etl_neotass.py', '--cfg-path', '/tmp/tmpd_p0o6km']
[2025-09-24T03:29:38.713+0000] {standard_task_runner.py:88} INFO - Job 9: Subtask extract
[2025-09-24T03:29:38.885+0000] {task_command.py:423} INFO - Running <TaskInstance: dag_etl.extract manual__2025-09-24T03:29:29.961297+00:00 [running]> on host 83a6c0571584
[2025-09-24T03:29:39.169+0000] {taskinstance.py:2480} INFO - Exporting env vars: AIRFLOW_CTX_DAG_OWNER='***' AIRFLOW_CTX_DAG_ID='dag_etl' AIRFLOW_CTX_TASK_ID='extract' AIRFLOW_CTX_EXECUTION_DATE='2025-09-24T03:29:29.961297+00:00' AIRFLOW_CTX_TRY_NUMBER='1' AIRFLOW_CTX_DAG_RUN_ID='manual__2025-09-24T03:29:29.961297+00:00'
[2025-09-24T03:29:39.459+0000] {taskinstance.py:2698} ERROR - Task failed with exception
Traceback (most recent call last):
  File "/home/airflow/.local/lib/python3.8/site-packages/airflow/models/taskinstance.py", line 433, in _execute_task
    result = execute_callable(context=context, **execute_callable_kwargs)
  File "/home/airflow/.local/lib/python3.8/site-packages/airflow/operators/python.py", line 199, in execute
    return_value = self.execute_callable()
  File "/home/airflow/.local/lib/python3.8/site-packages/airflow/operators/python.py", line 216, in execute_callable
    return self.python_callable(*self.op_args, **self.op_kwargs)
  File "/opt/airflow/dags/dag_etl_neotass.py", line 27, in extract
    data_oportunidades = pd.read_json('../database/registros_oportunidades.json')
  File "/home/airflow/.local/lib/python3.8/site-packages/pandas/io/json/_json.py", line 760, in read_json
    json_reader = JsonReader(
  File "/home/airflow/.local/lib/python3.8/site-packages/pandas/io/json/_json.py", line 861, in __init__
    data = self._get_data_from_filepath(filepath_or_buffer)
  File "/home/airflow/.local/lib/python3.8/site-packages/pandas/io/json/_json.py", line 917, in _get_data_from_filepath
    raise FileNotFoundError(f"File {filepath_or_buffer} does not exist")
FileNotFoundError: File ../database/registros_oportunidades.json does not exist
[2025-09-24T03:29:39.543+0000] {taskinstance.py:1138} INFO - Marking task as UP_FOR_RETRY. dag_id=dag_etl, task_id=extract, execution_date=20250924T032929, start_date=20250924T032938, end_date=20250924T032939
[2025-09-24T03:29:39.643+0000] {standard_task_runner.py:107} ERROR - Failed to execute job 9 for task extract (File ../database/registros_oportunidades.json does not exist; 1215)
[2025-09-24T03:29:39.709+0000] {local_task_job_runner.py:234} INFO - Task exited with return code 1
[2025-09-24T03:29:39.854+0000] {taskinstance.py:3280} INFO - 0 downstream tasks scheduled from follow-on schedule check
